Workbook
Name SegmentaciónDeDatos_ID: #N/A

Sheet Datos
A1: ID | B1: Nombre completo | C1: Número de carnet | D1: Año de ingreso | E1: Facultad | F1: Frecuencia de uso de IA | G1: ChatGPT | H1: Copilot | I1: Gemini | J1: Grok | K1: Deepseek | L1: Otra IA | M1: Horas semanales de IA | N1: Frecuencia - Explicar un concepto | O1: Frecuencia - Resumir un artículo | P1: Frecuencia - Ideas para investigación | Q1: Frecuencia - Estructurar ideas | R1: Frecuencia - Generar y editar texto | S1: Frecuencia - Apoyos visuales | T1: Aceptabilidad - Explicar un concepto | U1: Aceptabilidad - Resumir un artículo | V1: Aceptabilidad - Ideas para investigación | W1: Aceptabilidad - Estructurar ideas | X1: Aceptabilidad - Generar y editar texto | Y1: Aceptabilidad - Apoyos visuales | Z1: Ranking de razones | AA1: Razón principal | AB1: IA ayuda a entender temas complejos | AC1: Facilidad de uso de IA | AD1: Confianza en resultados | AE1: Intención de seguir usando IA | AF1: Satisfacción general | AG1: Situaciones experimentadas | AH1: Influencia principal | AI1: Percepción de política universitaria | AJ1: Verificación de información | AK1: Cambio percibido en calidad | AL1: Conciencia de riesgos | AM1: Disposición a capacitación | AN1: Preocupación principal
A2: 14 | B2: Emileny Isabel Mazariegos Zepeda | C2: 1200723 | D2: =IFERROR(2000+VALUE(RIGHT(C2,2)),"Sin dato") -> 2023 | E2: Ingeniería | F2: Semanalmente | G2: Mensual | H2: Rara vez | I2: Semanal | J2: Nunca | K2: Nunca | L2: Semanal | M2: Menos de 1 hora | N2: Frecuentemente | O2: Frecuentemente | P2: Rara vez | Q2: Algunas veces | R2: Algunas veces | S2: Rara vez | T2: Totalmente aceptable | U2: Totalmente aceptable | V2: Neutral | W2: Neutral | X2: Neutral | Y2: Aceptable | Z2: Para obtener mejores notas o rendir mejor;Para entender material complejo;Para ahorrar tiempo en tareas;Para prepararme para mi futura carrera; | AA2: Para obtener mejores notas o rendir mejor | AB2: Totalmente de acuerdo | AC2: De acuerdo | AD2: En desacuerdo | AE2: De acuerdo | AF2: De acuerdo | AG2: Siento que dependo de la IA para producir un mejor trabajo; | AH2: Influencia de compañeros de estudio | AI2: Se anima a usarla, pero con límites claros | AJ2: Frecuentemente | AK2: Ha mejorado algo | AL2: Consciente | AM2: Poco dispuesto | AN2: Que afecte mi aprendizaje
A3: 15 | B3: Pablo Esteban Oliva Morales | C3: 1076726 | D3: =IFERROR(2000+VALUE(RIGHT(C3,2)),"Sin dato") -> 2026 | E3: Ingeniería | F3: A diario | G3: Semanal | H3: Nunca | I3: Diario | J3: Nunca | K3: Semanal | L3: Diario | M3: Más de 10 horas | N3: Siempre | O3: Siempre | P3: Siempre | Q3: Siempre | R3: Siempre | S3: Siempre | T3: Totalmente aceptable | U3: Aceptable | V3: Neutral | W3: Totalmente aceptable | X3: Neutral | Y3: Totalmente aceptable | Z3: Para ahorrar tiempo en tareas;Para obtener mejores notas o rendir mejor;Para prepararme para mi futura carrera;Para entender material complejo; | AA3: Para ahorrar tiempo en tareas | AB3: Totalmente de acuerdo | AC3: Totalmente de acuerdo | AD3: En desacuerdo | AE3: Totalmente de acuerdo | AF3: Totalmente de acuerdo | AG3: Me resulta más difícil trabajar o estudiar sin usar IA;Siento que dependo de la IA para producir un mejor trabajo; | AH3: Decisión propia | AI3: Se desalienta, permitida en pocos casos | AJ3: Frecuentemente | AK3: Ha mejorado mucho | AL3: Consciente | AM3: Poco dispuesto | AN3: Que afecte mi aprendizaje
A4: 16 | B4: Carlos Andrés Pérez Castañeda | C4: 1224025 | D4: =IFERROR(2000+VALUE(RIGHT(C4,2)),"Sin dato") -> 2025 | E4: Ingeniería | F4: A diario | G4: Semanal | H4: Rara vez | I4: Diario | J4: Nunca | K4: Rara vez | L4: Diario | M4: 3 a 6 horas | N4: Siempre | O4: Siempre | P4: Siempre | Q4: Siempre | R4: Siempre | S4: Siempre | T4: Totalmente aceptable | U4: Aceptable | V4: Totalmente aceptable | W4: Neutral | X4: Neutral | Y4: Totalmente aceptable | Z4: Para entender material complejo;Para obtener mejores notas o rendir mejor;Para ahorrar tiempo en tareas;Para prepararme para mi futura carrera; | AA4: Para entender material complejo | AB4: Totalmente de acuerdo | AC4: Totalmente de acuerdo | AD4: De acuerdo | AE4: Totalmente de acuerdo | AF4: Totalmente de acuerdo | AG4: Me resulta más difícil trabajar o estudiar sin usar IA;Siento que dependo de la IA para producir un mejor trabajo; | AH4: Decisión propia | AI4: Se anima a usarla, pero con límites claros | AJ4: Frecuentemente | AK4: Ha mejorado algo | AL4: Moderadamente consciente | AM4: Neutral | AN4: Que afecte mi aprendizaje
A5: 17 | B5: Hans Dieter Majus Arévalo | C5: 1025626 | D5: =IFERROR(2000+VALUE(RIGHT(C5,2)),"Sin dato") -> 2026 | E5: Ingeniería | F5: A diario | G5: Semanal | H5: Nunca | I5: Semanal | J5: Nunca | K5: Nunca | L5: Nunca | M5: 1 a 3 horas | N5: Algunas veces | O5: Siempre | P5: Rara vez | Q5: Rara vez | R5: Frecuentemente | S5: Rara vez | T5: Totalmente aceptable | U5: Aceptable | V5: Totalmente aceptable | W5: Totalmente aceptable | X5: Totalmente aceptable | Y5: Neutral | Z5: Para entender material complejo;Para ahorrar tiempo en tareas;Para obtener mejores notas o rendir mejor;Para prepararme para mi futura carrera; | AA5: Para entender material complejo | AB5: Neutral | AC5: De acuerdo | AD5: Neutral | AE5: Neutral | AF5: Neutral | AG5: No he experimentado ninguna de estas situaciones; | AH5: Decisión propia | AI5: Se desalienta, permitida en pocos casos | AJ5: Siempre | AK5: Ha mejorado algo | AL5: Muy consciente | AM5: Neutral | AN5: No tengo ninguna preocupación
A6: 18 | B6: María Fernanda Castillo Rodríguez | C6: 1268226 | D6: =IFERROR(2000+VALUE(RIGHT(C6,2)),"Sin dato") -> 2026 | E6: Humanidades | F6: Semanalmente | G6: Semanal | H6: Nunca | I6: Mensual | J6: Nunca | K6: Nunca | L6: Mensual | M6: Menos de 1 hora | N6: Algunas veces | O6: Frecuentemente | P6: Algunas veces | Q6: Algunas veces | R6: Rara vez | S6: Nunca | T6: Aceptable | U6: Aceptable | V6: Aceptable | W6: Aceptable | X6: Poco aceptable | Y6: Neutral | Z6: Para entender material complejo;Para ahorrar tiempo en tareas;Para obtener mejores notas o rendir mejor;Para prepararme para mi futura carrera; | AA6: Para entender material complejo | AB6: Neutral | AC6: De acuerdo | AD6: Neutral | AE6: De acuerdo | AF6: Neutral | AG6: No he experimentado ninguna de estas situaciones; | AH6: Decisión propia | AI6: Se anima a usarla, pero con límites claros | AJ6: Frecuentemente | AK6: No ha cambiado | AL6: Consciente | AM6: Neutral | AN6: Que la información proporcionada sea incorrecta
A7: 19 | B7: Julio José Laynez Muñiz | C7: 1318024 | D7: =IFERROR(2000+VALUE(RIGHT(C7,2)),"Sin dato") -> 2024 | E7: Humanidades | F7: Semanalmente | G7: Semanal | H7: Nunca | I7: Semanal | J7: Nunca | K7: Nunca | L7: Nunca | M7: Menos de 1 hora | N7: Algunas veces | O7: Algunas veces | P7: Algunas veces | Q7: Algunas veces | R7: Rara vez | S7: Algunas veces | T7: Neutral | U7: Neutral | V7: Aceptable | W7: Poco aceptable | X7: Poco aceptable | Y7: Aceptable | Z7: Para entender material complejo;Para ahorrar tiempo en tareas;Para prepararme para mi futura carrera;Para obtener mejores notas o rendir mejor; | AA7: Para entender material complejo | AB7: De acuerdo | AC7: Neutral | AD7: En desacuerdo | AE7: Neutral | AF7: Neutral | AG7: Me resulta más difícil trabajar o estudiar sin usar IA;Siento que retengo menos información cuando uso IA para resolver algo; | AH7: Sugerencia de un catedrático | AI7: Está prohibida por completo | AJ7: Algunas veces | AK7: No ha cambiado | AL7: Consciente | AM7: Neutral | AN7: Que afecte mi aprendizaje
A8: 20 | B8: María Renee Girón | C8: 1293926 | D8: =IFERROR(2000+VALUE(RIGHT(C8,2)),"Sin dato") -> 2026 | E8: Humanidades | F8: Semanalmente | G8: Mensual | H8: Nunca | I8: Nunca | J8: Nunca | K8: Nunca | L8: Mensual | M8: Menos de 1 hora | N8: Algunas veces | O8: Rara vez | P8: Nunca | Q8: Algunas veces | R8: Rara vez | S8: Nunca | T8: Neutral | U8: Poco aceptable | V8: Totalmente inaceptable | W8: Aceptable | X8: Poco aceptable | Y8: Aceptable | Z8: Para entender material complejo;Para ahorrar tiempo en tareas;Para obtener mejores notas o rendir mejor;Para prepararme para mi futura carrera; | AA8: Para entender material complejo | AB8: Neutral | AC8: Neutral | AD8: En desacuerdo | AE8: Neutral | AF8: Neutral | AG8: No he experimentado ninguna de estas situaciones; | AH8: Sugerencia de un catedrático | AI8: Se anima a usarla, pero con límites claros | AJ8: Siempre | AK8: No ha cambiado | AL8: Muy consciente | AM8: Muy dispuesto | AN8: Depender demasiado de la IA
A9: 21 | B9: Christopher André Ramos Samayoa | C9: 1025426 | D9: =IFERROR(2000+VALUE(RIGHT(C9,2)),"Sin dato") -> 2026 | E9: Ingeniería | F9: A diario | G9: Diario | H9: Nunca | I9: Nunca | J9: Nunca | K9: Nunca | L9: Nunca | M9: 1 a 3 horas | N9: Rara vez | O9: Algunas veces | P9: Frecuentemente | Q9: Nunca | R9: Nunca | S9: Algunas veces | T9: Totalmente aceptable | U9: Neutral | V9: Neutral | W9: Poco aceptable | X9: Poco aceptable | Y9: Aceptable | Z9: Para entender material complejo;Para prepararme para mi futura carrera;Para ahorrar tiempo en tareas;Para obtener mejores notas o rendir mejor; | AA9: Para entender material complejo | AB9: De acuerdo | AC9: Totalmente de acuerdo | AD9: Neutral | AE9: Neutral | AF9: De acuerdo | AG9: No he experimentado ninguna de estas situaciones; | AH9: Decisión propia | AI9: Se anima a usarla, pero con límites claros | AJ9: Siempre | AK9: Ha mejorado mucho | AL9: Consciente | AM9: Neutral | AN9: No tengo ninguna preocupación
A10: 22 | B10: Benjamín Alejandro Marroquín Rojas | C10: 1059225 | D10: =IFERROR(2000+VALUE(RIGHT(C10,2)),"Sin dato") -> 2025 | E10: Humanidades | F10: A diario | G10: Mensual | H10: Nunca | I10: Mensual | J10: Nunca | K10: Nunca | L10: Nunca | M10: 3 a 6 horas | N10: Rara vez | O10: Algunas veces | P10: Algunas veces | Q10: Rara vez | R10: Algunas veces | S10: Nunca | T10: Neutral | U10: Neutral | V10: Poco aceptable | W10: Neutral | X10: Poco aceptable | Y10: Neutral | Z10: Para entender material complejo;Para prepararme para mi futura carrera;Para ahorrar tiempo en tareas;Para obtener mejores notas o rendir mejor; | AA10: Para entender material complejo | AB10: De acuerdo | AC10: De acuerdo | AD10: Neutral | AE10: De acuerdo | AF10: De acuerdo | AG10: No he experimentado ninguna de estas situaciones; | AH10: Influencia de compañeros de estudio | AI10: Se anima a usarla, pero con límites claros | AJ10: Frecuentemente | AK10: Ha mejorado algo | AL10: Consciente | AM10: Neutral | AN10: Depender demasiado de la IA
A11: 23 | B11: Samuel Esteban Picón Choc | C11: 1308426 | D11: =IFERROR(2000+VALUE(RIGHT(C11,2)),"Sin dato") -> 2026 | E11: Ingeniería | F11: A diario | G11: Diario | H11: Nunca | I11: Diario | J11: Nunca | K11: Rara vez | L11: Diario | M11: 3 a 6 horas | N11: Frecuentemente | O11: Frecuentemente | P11: Frecuentemente | Q11: Rara vez | R11: Siempre | S11: Siempre | T11: Totalmente aceptable | U11: Neutral | V11: Neutral | W11: Totalmente aceptable | X11: Poco aceptable | Y11: Neutral | Z11: Para ahorrar tiempo en tareas;Para entender material complejo;Para obtener mejores notas o rendir mejor;Para prepararme para mi futura carrera; | AA11: Para ahorrar tiempo en tareas | AB11: Totalmente de acuerdo | AC11: Totalmente de acuerdo | AD11: En desacuerdo | AE11: Totalmente de acuerdo | AF11: De acuerdo | AG11: Siento que dependo de la IA para producir un mejor trabajo;Siento que retengo menos información cuando uso IA para resolver algo; | AH11: Decisión propia | AI11: No sé cuál es la política de mi universidad | AJ11: Algunas veces | AK11: Ha mejorado mucho | AL11: Consciente | AM11: Muy dispuesto | AN11: Incumplir las reglas de un curso o trabajo
A12: 24 | B12: Diana Paola Sandoval Pacheco | C12: 2984426 | D12: =IFERROR(2000+VALUE(RIGHT(C12,2)),"Sin dato") -> 2026 | E12: Ingeniería | F12: A diario | G12: Diario | H12: Nunca | I12: Rara vez | J12: Nunca | K12: Nunca | L12: Nunca | M12: 1 a 3 horas | N12: Siempre | O12: Siempre | P12: Siempre | Q12: Siempre | R12: Siempre | S12: Frecuentemente | T12: Totalmente aceptable | U12: Totalmente aceptable | V12: Totalmente aceptable | W12: Totalmente aceptable | X12: Totalmente aceptable | Y12: Totalmente aceptable | Z12: Para obtener mejores notas o rendir mejor;Para entender material complejo;Para ahorrar tiempo en tareas;Para prepararme para mi futura carrera; | AA12: Para obtener mejores notas o rendir mejor | AB12: Totalmente de acuerdo | AC12: Totalmente de acuerdo | AD12: Neutral | AE12: Totalmente de acuerdo | AF12: Neutral | AG12: No he experimentado ninguna de estas situaciones; | AH12: Decisión propia | AI12: Se anima a usarla, pero con límites claros | AJ12: Rara vez | AK12: Ha mejorado mucho | AL12: Consciente | AM12: Dispuesto | AN12: Que la información proporcionada sea incorrecta
A13: 25 | B13: Camila De León Rivera | C13: 1114426 | D13: =IFERROR(2000+VALUE(RIGHT(C13,2)),"Sin dato") -> 2026 | E13: Humanidades | F13: Mensualmente | G13: Mensual | H13: Nunca | I13: Nunca | J13: Rara vez | K13: Nunca | L13: Mensual | M13: Menos de 1 hora | N13: Frecuentemente | O13: Frecuentemente | P13: Rara vez | Q13: Algunas veces | R13: Nunca | S13: Rara vez | T13: Totalmente aceptable | U13: Neutral | V13: Neutral | W13: Aceptable | X13: Totalmente inaceptable | Y13: Aceptable | Z13: Para entender material complejo;Para obtener mejores notas o rendir mejor;Para prepararme para mi futura carrera;Para ahorrar tiempo en tareas; | AA13: Para entender material complejo | AB13: Totalmente de acuerdo | AC13: Neutral | AD13: De acuerdo | AE13: Neutral | AF13: Neutral | AG13: Me resulta más difícil trabajar o estudiar sin usar IA; | AH13: Decisión propia | AI13: Se desalienta, permitida en pocos casos | AJ13: Frecuentemente | AK13: Ha mejorado algo | AL13: Muy consciente | AM13: Poco dispuesto | AN13: Que la información proporcionada sea incorrecta
A14: 26 | B14: Jose Manuel Morales Perez | C14: 1066422 | D14: =IFERROR(2000+VALUE(RIGHT(C14,2)),"Sin dato") -> 2022 | E14: Ingeniería | F14: A diario | G14: Mensual | H14: Rara vez | I14: Rara vez | J14: Diario | K14: Nunca | L14: Rara vez | M14: Menos de 1 hora | N14: Rara vez | O14: Frecuentemente | P14: Siempre | Q14: Frecuentemente | R14: Rara vez | S14: Algunas veces | T14: Neutral | U14: Aceptable | V14: Aceptable | W14: Totalmente aceptable | X14: Poco aceptable | Y14: Neutral | Z14: Para entender material complejo;Para ahorrar tiempo en tareas;Para obtener mejores notas o rendir mejor;Para prepararme para mi futura carrera; | AA14: Para entender material complejo | AB14: Neutral | AC14: Totalmente de acuerdo | AD14: Neutral | AE14: Totalmente de acuerdo | AF14: De acuerdo | AG14: Me resulta más difícil trabajar o estudiar sin usar IA; | AH14: Decisión propia | AI14: No sé cuál es la política de mi universidad | AJ14: Frecuentemente | AK14: Ha mejorado algo | AL14: Muy consciente | AM14: Neutral | AN14: Depender demasiado de la IA
... A17: 29 | B17: Sara Emperatriz Ortíz Campos | C17: 122423 | D17: =IFERROR(2000+VALUE(RIGHT(C17,2)),"Sin dato") -> 2023 | E17: Humanidades | F17: Semanalmente | G17: Semanal | H17: Nunca | I17: Semanal | J17: Nunca | K17: Semanal | L17: Nunca | M17: 3 a 6 horas | N17: Rara vez | O17: Rara vez | P17: Frecuentemente | Q17: Algunas veces | R17: Frecuentemente | S17: Frecuentemente | T17: Totalmente inaceptable | U17: Totalmente inaceptable | V17: Totalmente inaceptable | W17: Aceptable | X17: Totalmente inaceptable | Y17: Totalmente inaceptable | Z17: Para ahorrar tiempo en tareas;Para obtener mejores notas o rendir mejor;Para entender material complejo;Para prepararme para mi futura carrera; | AA17: Para ahorrar tiempo en tareas | AB17: De acuerdo | AC17: Totalmente de acuerdo | AD17: Neutral | AE17: Totalmente de acuerdo | AF17: Totalmente de acuerdo | AG17: No he experimentado ninguna de estas situaciones; | AH17: Decisión propia | AI17: Se anima a usarla, pero con límites claros | AJ17: Siempre | AK17: Ha mejorado mucho | AL17: Muy consciente | AM17: Muy dispuesto | AN17: Que la información proporcionada sea incorrecta
A18: 30 | B18: Diego Caal | C18: 123422 | D18: =IFERROR(2000+VALUE(RIGHT(C18,2)),"Sin dato") -> 2022 | E18: Humanidades | F18: Mensualmente | G18: Mensual | H18: Mensual | I18: Semanal | J18: Nunca | K18: Nunca | L18: Nunca | M18: 1 a 3 horas | N18: Algunas veces | O18: Rara vez | P18: Rara vez | Q18: Rara vez | R18: Rara vez | S18: Frecuentemente | T18: Aceptable | U18: Aceptable | V18: Neutral | W18: Aceptable | X18: Poco aceptable | Y18: Aceptable | Z18: Para ahorrar tiempo en tareas;Para entender material complejo;Para prepararme para mi futura carrera;Para obtener mejores notas o rendir mejor; | AA18: Para ahorrar tiempo en tareas | AB18: De acuerdo | AC18: Neutral | AD18: Totalmente en desacuerdo | AE18: De acuerdo | AF18: De acuerdo | AG18: Siento que retengo menos información cuando uso IA para resolver algo; | AH18: Decisión propia | AI18: Se anima a usarla, pero con límites claros | AJ18: Rara vez | AK18: No ha cambiado | AL18: Consciente | AM18: Dispuesto | AN18: Que afecte mi aprendizaje
A19: 31 | B19: Allison Fuentes | C19: 1084723 | D19: =IFERROR(2000+VALUE(RIGHT(C19,2)),"Sin dato") -> 2023 | E19: Ingeniería | F19: A diario | G19: Diario | H19: Nunca | I19: Mensual | J19: Nunca | K19: Nunca | L19: Nunca | M19: 1 a 3 horas | N19: Frecuentemente | O19: Frecuentemente | P19: Algunas veces | Q19: Frecuentemente | R19: Siempre | S19: Frecuentemente | T19: Totalmente aceptable | U19: Neutral | V19: Aceptable | W19: Aceptable | X19: Poco aceptable | Y19: Aceptable | Z19: Para entender material complejo;Para ahorrar tiempo en tareas;Para obtener mejores notas o rendir mejor;Para prepararme para mi futura carrera; | AA19: Para entender material complejo | AB19: De acuerdo | AC19: De acuerdo | AD19: Neutral | AE19: Totalmente de acuerdo | AF19: De acuerdo | AG19: Siento que retengo menos información cuando uso IA para resolver algo; | AH19: Decisión propia | AI19: Se anima a usarla, pero con límites claros | AJ19: Algunas veces | AK19: Ha mejorado algo | AL19: Consciente | AM19: Poco dispuesto | AN19: Que la información proporcionada sea incorrecta
A20: 32 | B20: Pamela Díaz | C20: 1106922 | D20: =IFERROR(2000+VALUE(RIGHT(C20,2)),"Sin dato") -> 2022 | E20: Humanidades | F20: A diario | G20: Diario | H20: Nunca | I20: Rara vez | J20: Nunca | K20: Nunca | L20: Rara vez | M20: 6 a 10 horas | N20: Frecuentemente | O20: Siempre | P20: Algunas veces | Q20: Frecuentemente | R20: Siempre | S20: Algunas veces | T20: Neutral | U20: Totalmente aceptable | V20: Aceptable | W20: Aceptable | X20: Aceptable | Y20: Aceptable | Z20: Para ahorrar tiempo en tareas;Para entender material complejo;Para obtener mejores notas o rendir mejor;Para prepararme para mi futura carrera; | AA20: Para ahorrar tiempo en tareas | AB20: Totalmente de acuerdo | AC20: De acuerdo | AD20: Neutral | AE20: Totalmente de acuerdo | AF20: De acuerdo | AG20: Me resulta más difícil trabajar o estudiar sin usar IA;Siento que retengo menos información cuando uso IA para resolver algo; | AH20: Influencia de compañeros de estudio | AI20: Se anima a usarla, pero con límites claros | AJ20: Frecuentemente | AK20: Ha mejorado algo | AL20: Consciente | AM20: Neutral | AN20: Que la información proporcionada sea incorrecta
A21: 33 | B21: Sharon Cienfuegos | C21: 1253221 | D21: =IFERROR(2000+VALUE(RIGHT(C21,2)),"Sin dato") -> 2021 | E21: Ingeniería | F21: Nunca | G21: Nunca | H21: Nunca | I21: Nunca | J21: Nunca | K21: Nunca | L21: Nunca | M21: 3 a 6 horas | N21: Nunca | O21: Nunca | P21: Nunca | Q21: Nunca | R21: Algunas veces | S21: Nunca | T21: Totalmente inaceptable | U21: Totalmente inaceptable | V21: Totalmente inaceptable | W21: Totalmente inaceptable | X21: Totalmente inaceptable | Y21: Totalmente inaceptable | Z21: Para entender material complejo;Para prepararme para mi futura carrera;Para ahorrar tiempo en tareas;Para obtener mejores notas o rendir mejor; | AA21: Para entender material complejo | AB21: Totalmente en desacuerdo | AC21: Totalmente en desacuerdo | AD21: Totalmente en desacuerdo | AE21: Totalmente en desacuerdo | AF21: Totalmente en desacuerdo | AG21: Me resulta más difícil trabajar o estudiar sin usar IA; | AH21: Sugerencia de un catedrático | AI21: Se anima a usarla, pero con límites claros | AJ21: Frecuentemente | AK21: Ha mejorado algo | AL21: Consciente | AM21: Dispuesto | AN21: Que afecte mi aprendizaje
A22: 34 | B22: Carolina Cienfuegos | C22: 1353225 | D22: =IFERROR(2000+VALUE(RIGHT(C22,2)),"Sin dato") -> 2025 | E22: Ingeniería | F22: Nunca | G22: Nunca | H22: Nunca | I22: Nunca | J22: Nunca | K22: Nunca | L22: Nunca | M22: Menos de 1 hora | N22: Rara vez | O22: Rara vez | P22: Rara vez | Q22: Rara vez | R22: Rara vez | S22: Rara vez | T22: Neutral | U22: Neutral | V22: Neutral | W22: Neutral | X22: Neutral | Y22: Neutral | Z22: Para entender material complejo;Para obtener mejores notas o rendir mejor;Para prepararme para mi futura carrera;Para ahorrar tiempo en tareas; | AA22: Para entender material complejo | AB22: En desacuerdo | AC22: En desacuerdo | AD22: En desacuerdo | AE22: En desacuerdo | AF22: En desacuerdo | AG22: No he experimentado ninguna de estas situaciones; | AH22: Influencia de compañeros de estudio | AI22: No sé cuál es la política de mi universidad | AJ22: Frecuentemente | AK22: Ha mejorado mucho | AL22: Muy consciente | AM22: Nada dispuesto | AN22: No tengo ninguna preocupación
A23: 35 | B23: Rolando Javier Espinoza Del Cid | C23: 2285019 | D23: =IFERROR(2000+VALUE(RIGHT(C23,2)),"Sin dato") -> 2019 | E23: Ingeniería | F23: Rara vez (algunas veces al mes) | G23: Mensual | H23: Rara vez | I23: Rara vez | J23: Rara vez | K23: Nunca | L23: Nunca | M23: Menos de 1 hora | N23: Nunca | O23: Nunca | P23: Nunca | Q23: Nunca | R23: Nunca | S23: Nunca | T23: Totalmente inaceptable | U23: Totalmente inaceptable | V23: Poco aceptable | W23: Poco aceptable | X23: Poco aceptable | Y23: Poco aceptable | Z23: Para ahorrar tiempo en tareas;Para obtener mejores notas o rendir mejor;Para entender material complejo;Para prepararme para mi futura carrera; | AA23: Para ahorrar tiempo en tareas | AB23: Neutral | AC23: Totalmente en desacuerdo | AD23: Totalmente en desacuerdo | AE23: Totalmente en desacuerdo | AF23: Totalmente en desacuerdo | AG23: Siento que dependo de la IA para producir un mejor trabajo; | AH23: Requisito de un curso o trabajo | AI23: Se anima a usarla, pero con límites claros | AJ23: Frecuentemente | AK23: Ha mejorado algo | AL23: Consciente | AM23: Dispuesto | AN23: Depender demasiado de la IA
A24: 36 | B24: Ana Mayra Godinez | C24: 1279024 | D24: =IFERROR(2000+VALUE(RIGHT(C24,2)),"Sin dato") -> 2024 | E24: Humanidades | F24: A diario | G24: Diario | H24: Rara vez | I24: Rara vez | J24: Nunca | K24: Nunca | L24: Semanal | M24: Menos de 1 hora | N24: Algunas veces | O24: Algunas veces | P24: Frecuentemente | Q24: Siempre | R24: Siempre | S24: Rara vez | T24: Totalmente aceptable | U24: Neutral | V24: Neutral | W24: Totalmente aceptable | X24: Neutral | Y24: Poco aceptable | Z24: Para ahorrar tiempo en tareas;Para entender material complejo;Para prepararme para mi futura carrera;Para obtener mejores notas o rendir mejor; | AA24: Para ahorrar tiempo en tareas | AB24: Totalmente de acuerdo | AC24: Totalmente de acuerdo | AD24: Neutral | AE24: De acuerdo | AF24: Neutral | AG24: Siento que dependo de la IA para producir un mejor trabajo; | AH24: Decisión propia | AI24: Se desalienta, permitida en pocos casos | AJ24: Frecuentemente | AK24: Ha empeorado algo | AL24: Muy consciente | AM24: Muy dispuesto | AN24: Depender demasiado de la IA
A25: 37 | B25: Allan Leonel Rojas Cortave | C25: 1100121 | D25: =IFERROR(2000+VALUE(RIGHT(C25,2)),"Sin dato") -> 2021 | E25: Humanidades | F25: A diario | G25: Diario | H25: Nunca | I25: Nunca | J25: Rara vez | K25: Rara vez | L25: Nunca | M25: 3 a 6 horas | N25: Rara vez | O25: Siempre | P25: Siempre | Q25: Siempre | R25: Siempre | S25: Algunas veces | T25: Aceptable | U25: Aceptable | V25: Neutral | W25: Totalmente aceptable | X25: Totalmente aceptable | Y25: Totalmente aceptable | Z25: Para ahorrar tiempo en tareas;Para entender material complejo;Para obtener mejores notas o rendir mejor;Para prepararme para mi futura carrera; | AA25: Para ahorrar tiempo en tareas | AB25: Totalmente de acuerdo | AC25: Totalmente de acuerdo | AD25: De acuerdo | AE25: Totalmente de acuerdo | AF25: Totalmente de acuerdo | AG25: Me resulta más difícil trabajar o estudiar sin usar IA; | AH25: Decisión propia | AI25: No sé cuál es la política de mi universidad | AJ25: Rara vez | AK25: Ha mejorado mucho | AL25: Poco consciente | AM25: Muy dispuesto | AN25: Depender demasiado de la IA
A26: 38 | B26: Natalia Moscoso | C26: 1214121 | D26: =IFERROR(2000+VALUE(RIGHT(C26,2)),"Sin dato") -> 2021 | E26: Humanidades | F26: Semanalmente | G26: Rara vez | H26: Rara vez | I26: Semanal | J26: Nunca | K26: Nunca | L26: Nunca | M26: Menos de 1 hora | N26: Frecuentemente | O26: Frecuentemente | P26: Rara vez | Q26: Frecuentemente | R26: Rara vez | S26: Algunas veces | T26: Totalmente aceptable | U26: Totalmente aceptable | V26: Totalmente aceptable | W26: Totalmente aceptable | X26: Aceptable | Y26: Totalmente aceptable | Z26: Para ahorrar tiempo en tareas;Para entender material complejo;Para obtener mejores notas o rendir mejor;Para prepararme para mi futura carrera; | AA26: Para ahorrar tiempo en tareas | AB26: Totalmente de acuerdo | AC26: De acuerdo | AD26: Neutral | AE26: De acuerdo | AF26: De acuerdo | AG26: No he experimentado ninguna de estas situaciones; | AH26: Otro | AI26: No sé cuál es la política de mi universidad | AJ26: Algunas veces | AK26: Ha mejorado algo | AL26: Moderadamente consciente | AM26: Dispuesto | AN26: Depender demasiado de la IA
A27: 39 | B27: Pilar Coronado | C27: 1070022 | D27: =IFERROR(2000+VALUE(RIGHT(C27,2)),"Sin dato") -> 2022 | E27: Ingeniería | F27: Semanalmente | G27: Semanal | H27: Nunca | I27: Diario | J27: Nunca | K27: Nunca | L27: Semanal | M27: Menos de 1 hora | N27: Algunas veces | O27: Rara vez | P27: Rara vez | Q27: Rara vez | R27: Frecuentemente | S27: Rara vez | T27: Aceptable | U27: Aceptable | V27: Aceptable | W27: Aceptable | X27: Neutral | Y27: Aceptable | Z27: Para ahorrar tiempo en tareas;Para entender material complejo;Para obtener mejores notas o rendir mejor;Para prepararme para mi futura carrera; | AA27: Para ahorrar tiempo en tareas | AB27: De acuerdo | AC27: De acuerdo | AD27: Neutral | AE27: De acuerdo | AF27: Neutral | AG27: Me resulta más difícil trabajar o estudiar sin usar IA;Siento que dependo de la IA para producir un mejor trabajo;Siento que retengo menos información cuando uso IA para resolver algo; | AH27: Decisión propia | AI27: Se anima a usarla, pero con límites claros | AJ27: Siempre | AK27: Ha mejorado algo | AL27: Consciente | AM27: Dispuesto | AN27: Depender demasiado de la IA
A28: 40 | B28: José Mauricio Salazar Iguardia | C28: 1153026 | D28: =IFERROR(2000+VALUE(RIGHT(C28,2)),"Sin dato") -> 2026 | E28: Humanidades | F28: A diario | G28: Semanal | H28: Rara vez | I28: Diario | J28: Nunca | K28: Nunca | L28: Rara vez | M28: 1 a 3 horas | N28: Frecuentemente | O28: Frecuentemente | P28: Frecuentemente | Q28: Frecuentemente | R28: Frecuentemente | S28: Algunas veces | T28: Totalmente aceptable | U28: Totalmente aceptable | V28: Aceptable | W28: Aceptable | X28: Neutral | Y28: Totalmente aceptable | Z28: Para ahorrar tiempo en tareas;Para entender material complejo;Para obtener mejores notas o rendir mejor;Para prepararme para mi futura carrera; | AA28: Para ahorrar tiempo en tareas | AB28: Totalmente de acuerdo | AC28: De acuerdo | AD28: Neutral | AE28: Totalmente de acuerdo | AF28: Totalmente de acuerdo | AG28: Siento que dependo de la IA para producir un mejor trabajo;Me resulta más difícil trabajar o estudiar sin usar IA; | AH28: Decisión propia | AI28: Se anima a usarla, pero con límites claros | AJ28: Algunas veces | AK28: Ha mejorado algo | AL28: Moderadamente consciente | AM28: Dispuesto | AN28: Que la información proporcionada sea incorrecta
A29: 41 | B29: Yelsi Yuleidi Chilel Gabriel | C29: 1245623 | D29: =IFERROR(2000+VALUE(RIGHT(C29,2)),"Sin dato") -> 2023 | E29: Ingeniería | F29: Semanalmente | G29: Rara vez | H29: Nunca | I29: Rara vez | J29: Nunca | K29: Nunca | L29: Semanal | M29: 1 a 3 horas | N29: Rara vez | O29: Algunas veces | P29: Algunas veces | Q29: Algunas veces | R29: Algunas veces | S29: Algunas veces | T29: Neutral | U29: Neutral | V29: Aceptable | W29: Aceptable | X29: Aceptable | Y29: Neutral | Z29: Para ahorrar tiempo en tareas;Para obtener mejores notas o rendir mejor;Para entender material complejo;Para prepararme para mi futura carrera; | AA29: Para ahorrar tiempo en tareas | AB29: Neutral | AC29: Neutral | AD29: Neutral | AE29: De acuerdo | AF29: De acuerdo | AG29: Siento que retengo menos información cuando uso IA para resolver algo; | AH29: Influencia de compañeros de estudio | AI29: Se desalienta, permitida en pocos casos | AJ29: Siempre | AK29: Ha mejorado algo | AL29: Muy consciente | AM29: Neutral | AN29: Que afecte mi aprendizaje
A30: 42 | B30: Marcela Meléndez | C30: 1157722 | D30: =IFERROR(2000+VALUE(RIGHT(C30,2)),"Sin dato") -> 2022 | E30: Ingeniería | F30: Semanalmente | G30: Semanal | H30: Rara vez | I30: Mensual | J30: Nunca | K30: Nunca | L30: Mensual | M30: 1 a 3 horas | N30: Frecuentemente | O30: Frecuentemente | P30: Frecuentemente | Q30: Frecuentemente | R30: Frecuentemente | S30: Frecuentemente | T30: Aceptable | U30: Aceptable | V30: Aceptable | W30: Aceptable | X30: Aceptable | Y30: Aceptable | Z30: Para ahorrar tiempo en tareas;Para entender material complejo;Para obtener mejores notas o rendir mejor;Para prepararme para mi futura carrera; | AA30: Para ahorrar tiempo en tareas | AB30: De acuerdo | AC30: De acuerdo | AD30: De acuerdo | AE30: De acuerdo | AF30: De acuerdo | AG30: Me resulta más difícil trabajar o estudiar sin usar IA; | AH30: Decisión propia | AI30: Se anima a usarla, pero con límites claros | AJ30: Frecuentemente | AK30: Ha mejorado algo | AL30: Consciente | AM30: Dispuesto | AN30: Depender demasiado de la IA
A31: 43 | B31: Yuliana Maria Luna Ruiz Morales | C31: 1322525 | D31: =IFERROR(2000+VALUE(RIGHT(C31,2)),"Sin dato") -> 2025 | E31: Humanidades | F31: Mensualmente | G31: Mensual | H31: Nunca | I31: Mensual | J31: Nunca | K31: Nunca | L31: Nunca | M31: Menos de 1 hora | N31: Frecuentemente | O31: Frecuentemente | P31: Algunas veces | Q31: Algunas veces | R31: Rara vez | S31: Nunca | T31: Aceptable | U31: Aceptable | V31: Aceptable | W31: Aceptable | X31: Aceptable | Y31: Neutral | Z31: Para entender material complejo;Para obtener mejores notas o rendir mejor;Para prepararme para mi futura carrera;Para ahorrar tiempo en tareas; | AA31: Para entender material complejo | AB31: De acuerdo | AC31: Neutral | AD31: Neutral | AE31: Neutral | AF31: Neutral | AG31: No he experimentado ninguna de estas situaciones; | AH31: Decisión propia | AI31: Se desalienta, permitida en pocos casos | AJ31: Siempre | AK31: Ha mejorado algo | AL31: Muy consciente | AM31: Dispuesto | AN31: Depender demasiado de la IA
A32: 44 | B32: Juan Ramón Delgado Juárez | C32: 1006522 | D32: =IFERROR(2000+VALUE(RIGHT(C32,2)),"Sin dato") -> 2022 | E32: Humanidades | F32: A diario | G32: Mensual | H32: Nunca | I32: Semanal | J32: Nunca | K32: Nunca | L32: Rara vez | M32: Menos de 1 hora | N32: Frecuentemente | O32: Frecuentemente | P32: Algunas veces | Q32: Algunas veces | R32: Rara vez | S32: Nunca | T32: Aceptable | U32: Aceptable | V32: Aceptable | W32: Aceptable | X32: Poco aceptable | Y32: Neutral | Z32: Para ahorrar tiempo en tareas;Para entender material complejo;Para obtener mejores notas o rendir mejor;Para prepararme para mi futura carrera; | AA32: Para ahorrar tiempo en tareas | AB32: De acuerdo | AC32: De acuerdo | AD32: Neutral | AE32: De acuerdo | AF32: Neutral | AG32: Me resulta más difícil trabajar o estudiar sin usar IA; | AH32: Decisión propia | AI32: Se anima a usarla, pero con límites claros | AJ32: Frecuentemente | AK32: Ha mejorado algo | AL32: Consciente | AM32: Dispuesto | AN32: Depender demasiado de la IA
A33: 45 | B33: André Diaz Barrera | C33: 1262121 | D33: =IFERROR(2000+VALUE(RIGHT(C33,2)),"Sin dato") -> 2021 | E33: Humanidades | F33: A diario | G33: Semanal | H33: Rara vez | I33: Mensual | J33: Rara vez | K33: Nunca | L33: Rara vez | M33: 1 a 3 horas | N33: Frecuentemente | O33: Rara vez | P33: Algunas veces | Q33: Algunas veces | R33: Rara vez | S33: Algunas veces | T33: Aceptable | U33: Neutral | V33: Neutral | W33: Aceptable | X33: Totalmente inaceptable | Y33: Aceptable | Z33: Para ahorrar tiempo en tareas;Para entender material complejo;Para prepararme para mi futura carrera;Para obtener mejores notas o rendir mejor; | AA33: Para ahorrar tiempo en tareas | AB33: Totalmente de acuerdo | AC33: Neutral | AD33: En desacuerdo | AE33: De acuerdo | AF33: Neutral | AG33: No he experimentado ninguna de estas situaciones; | AH33: Influencia de compañeros de estudio | AI33: Se desalienta, permitida en pocos casos | AJ33: Frecuentemente | AK33: Ha mejorado algo | AL33: Consciente | AM33: Dispuesto | AN33: Que la información proporcionada sea incorrecta
A34: 46 | B34: Alicia Fortùn de Leòn | C34: 1097422 | D34: =IFERROR(2000+VALUE(RIGHT(C34,2)),"Sin dato") -> 2022 | E34: Humanidades | F34: A diario | G34: Semanal | H34: Rara vez | I34: Mensual | J34: Nunca | K34: Rara vez | L34: Rara vez | M34: Menos de 1 hora | N34: Frecuentemente | O34: Algunas veces | P34: Frecuentemente | Q34: Algunas veces | R34: Rara vez | S34: Nunca | T34: Aceptable | U34: Aceptable | V34: Neutral | W34: Aceptable | X34: Poco aceptable | Y34: Poco aceptable | Z34: Para entender material complejo;Para ahorrar tiempo en tareas;Para prepararme para mi futura carrera;Para obtener mejores notas o rendir mejor; | AA34: Para entender material complejo | AB34: De acuerdo | AC34: Neutral | AD34: Neutral | AE34: De acuerdo | AF34: De acuerdo | AG34: Siento que retengo menos información cuando uso IA para resolver algo;Me resulta más difícil trabajar o estudiar sin usar IA; | AH34: Decisión propia | AI34: Se anima a usarla, pero con límites claros | AJ34: Frecuentemente | AK34: Ha mejorado algo | AL34: Poco consciente | AM34: Dispuesto | AN34: Que la información proporcionada sea incorrecta
A35: 47 | B35: Karina Pérez García | C35: 1155917 | D35: =IFERROR(2000+VALUE(RIGHT(C35,2)),"Sin dato") -> 2017 | E35: Humanidades | F35: Semanalmente | G35: Semanal | H35: Nunca | I35: Nunca | J35: Nunca | K35: Nunca | L35: Mensual | M35: 1 a 3 horas | N35: Frecuentemente | O35: Algunas veces | P35: Siempre | Q35: Algunas veces | R35: Algunas veces | S35: Rara vez | T35: Aceptable | U35: Neutral | V35: Aceptable | W35: Aceptable | X35: Poco aceptable | Y35: Neutral | Z35: Para obtener mejores notas o rendir mejor;Para entender material complejo;Para ahorrar tiempo en tareas;Para prepararme para mi futura carrera; | AA35: Para obtener mejores notas o rendir mejor | AB35: Totalmente de acuerdo | AC35: De acuerdo | AD35: Neutral | AE35: De acuerdo | AF35: De acuerdo | AG35: Siento que retengo menos información cuando uso IA para resolver algo;Me resulta más difícil trabajar o estudiar sin usar IA; | AH35: Influencia de compañeros de estudio | AI35: Se desalienta, permitida en pocos casos | AJ35: Algunas veces | AK35: Ha mejorado mucho | AL35: Moderadamente consciente | AM35: Poco dispuesto | AN35: Que la información proporcionada sea incorrecta
A36: 48 | B36: Roberto Pivaral Chuy | C36: 1167321 | D36: =IFERROR(2000+VALUE(RIGHT(C36,2)),"Sin dato") -> 2021 | E36: Humanidades | F36: A diario | G36: Diario | H36: Nunca | I36: Mensual | J36: Rara vez | K36: Rara vez | L36: Semanal | M36: 1 a 3 horas | N36: Siempre | O36: Siempre | P36: Siempre | Q36: Frecuentemente | R36: Algunas veces | S36: Frecuentemente | T36: Aceptable | U36: Aceptable | V36: Aceptable | W36: Aceptable | X36: Aceptable | Y36: Aceptable | Z36: Para entender material complejo;Para ahorrar tiempo en tareas;Para obtener mejores notas o rendir mejor;Para prepararme para mi futura carrera; | AA36: Para entender material complejo | AB36: De acuerdo | AC36: De acuerdo | AD36: De acuerdo | AE36: Totalmente de acuerdo | AF36: De acuerdo | AG36: Me resulta más difícil trabajar o estudiar sin usar IA; | AH36: Decisión propia | AI36: Se anima a usarla, pero con límites claros | AJ36: Frecuentemente | AK36: Ha mejorado mucho | AL36: Moderadamente consciente | AM36: Dispuesto | AN36: Depender demasiado de la IA
A37: 49 | B37: Helen Villeda | C37: 2430921 | D37: =IFERROR(2000+VALUE(RIGHT(C37,2)),"Sin dato") -> 2021 | E37: Humanidades | F37: Semanalmente | G37: Semanal | H37: Nunca | I37: Semanal | J37: Rara vez | K37: Rara vez | L37: Nunca | M37: 1 a 3 horas | N37: Algunas veces | O37: Frecuentemente | P37: Algunas veces | Q37: Rara vez | R37: Frecuentemente | S37: Algunas veces | T37: Totalmente aceptable | U37: Aceptable | V37: Aceptable | W37: Aceptable | X37: Poco aceptable | Y37: Neutral | Z37: Para ahorrar tiempo en tareas;Para obtener mejores notas o rendir mejor;Para entender material complejo;Para prepararme para mi futura carrera; | AA37: Para ahorrar tiempo en tareas | AB37: Totalmente de acuerdo | AC37: De acuerdo | AD37: De acuerdo | AE37: Neutral | AF37: En desacuerdo | AG37: No he experimentado ninguna de estas situaciones; | AH37: Decisión propia | AI37: Se anima a usarla, pero con límites claros | AJ37: Frecuentemente | AK37: No ha cambiado | AL37: Consciente | AM37: Dispuesto | AN37: Depender demasiado de la IA
A38: 50 | B38: Ximena Quan | C38: 1138224 | D38: =IFERROR(2000+VALUE(RIGHT(C38,2)),"Sin dato") -> 2024 | E38: Ingeniería | F38: A diario | G38: Semanal | H38: Nunca | I38: Rara vez | J38: Nunca | K38: Nunca | L38: Nunca | M38: 1 a 3 horas | N38: Rara vez | O38: Frecuentemente | P38: Rara vez | Q38: Rara vez | R38: Siempre | S38: Rara vez | T38: Totalmente aceptable | U38: Aceptable | V38: Aceptable | W38: Aceptable | X38: Neutral | Y38: Aceptable | Z38: Para ahorrar tiempo en tareas;Para obtener mejores notas o rendir mejor;Para entender material complejo;Para prepararme para mi futura carrera; | AA38: Para ahorrar tiempo en tareas | AB38: Totalmente de acuerdo | AC38: Totalmente de acuerdo | AD38: Neutral | AE38: Totalmente de acuerdo | AF38: De acuerdo | AG38: Me resulta más difícil trabajar o estudiar sin usar IA;Siento que dependo de la IA para producir un mejor trabajo; | AH38: Decisión propia | AI38: Se anima a usarla, pero con límites claros | AJ38: Frecuentemente | AK38: Ha mejorado algo | AL38: Consciente | AM38: Dispuesto | AN38: Depender demasiado de la IA
A39: 51 | B39: Jeaneth Reyes Darlin | C39: 1265024 | D39: =IFERROR(2000+VALUE(RIGHT(C39,2)),"Sin dato") -> 2024 | E39: Ingeniería | F39: A diario | G39: Semanal | H39: Rara vez | I39: Mensual | J39: Rara vez | K39: Rara vez | L39: Semanal | M39: 3 a 6 horas | N39: Rara vez | O39: Siempre | P39: Siempre | Q39: Rara vez | R39: Frecuentemente | S39: Algunas veces | T39: Totalmente aceptable | U39: Neutral | V39: Aceptable | W39: Aceptable | X39: Neutral | Y39: Neutral | Z39: Para entender material complejo;Para obtener mejores notas o rendir mejor;Para ahorrar tiempo en tareas;Para prepararme para mi futura carrera; | AA39: Para entender material complejo | AB39: Totalmente de acuerdo | AC39: De acuerdo | AD39: En desacuerdo | AE39: De acuerdo | AF39: De acuerdo | AG39: Me resulta más difícil trabajar o estudiar sin usar IA; | AH39: Influencia de compañeros de estudio | AI39: Se anima a usarla, pero con límites claros | AJ39: Siempre | AK39: Ha mejorado algo | AL39: Consciente | AM39: Dispuesto | AN39: Que afecte mi aprendizaje
... A57: 69 | B57: Daniel Paz | C57: 1200022 | D57: =IFERROR(2000+VALUE(RIGHT(C57,2)),"Sin dato") -> 2022 | E57: Ingeniería | F57: A diario | G57: Diario | H57: Diario | I57: Diario | J57: Diario | K57: Diario | L57: Diario | M57: Más de 10 horas | N57: Nunca | O57: Nunca | P57: Nunca | Q57: Nunca | R57: Siempre | S57: Nunca | T57: Totalmente aceptable | U57: Totalmente aceptable | V57: Totalmente aceptable | W57: Totalmente aceptable | X57: Totalmente aceptable | Y57: Totalmente aceptable | Z57: Para ahorrar tiempo en tareas;Para entender material complejo;Para obtener mejores notas o rendir mejor;Para prepararme para mi futura carrera; | AA57: Para ahorrar tiempo en tareas | AB57: Totalmente de acuerdo | AC57: Totalmente de acuerdo | AD57: Totalmente de acuerdo | AE57: Totalmente de acuerdo | AF57: Totalmente de acuerdo | AG57: Me resulta más difícil trabajar o estudiar sin usar IA; | AH57: Sugerencia de un catedrático | AI57: Se desalienta, permitida en pocos casos | AJ57: Algunas veces | AK57: Ha mejorado algo | AL57: Muy consciente | AM57: Muy dispuesto | AN57: Que afecte mi aprendizaje

Sheet Calculos
A1: ID | B1: Incluido por filtros | D1: KPI | E1: Valor | S1: Dificultad sin IA | T1: Menor retención | U1: Dependencia | V1: Ninguna
A2: =Datos!A2 -> 14 | B2: =IF(AND(OR(#REF!="Todos",Datos!$E2=#REF!),OR(#REF!="Todos",Datos!$D2=IFERROR(VALUE(#REF!),#REF!)),OR(#REF!="Todos",Datos!$F2=#REF!)),1,0) -> #REF! | D2: Respuestas filtradas | E2: =SUM(B2:B57) -> #REF! | S2: =IF(ISNUMBER(SEARCH("Me resulta más difícil trabajar o estudiar sin usar IA",Datos!$AG2)),1,0) -> 0 | T2: =IF(ISNUMBER(SEARCH("Siento que retengo menos información cuando uso IA para resolver algo",Datos!$AG2)),1,0) -> 0 | U2: =IF(ISNUMBER(SEARCH("Siento que dependo de la IA para producir un mejor trabajo",Datos!$AG2)),1,0) -> 1 | V2: =IF(ISNUMBER(SEARCH("No he experimentado ninguna de estas situaciones",Datos!$AG2)),1,0) -> 0
A3: =Datos!A3 -> 15 | B3: =IF(AND(OR(#REF!="Todos",Datos!$E3=#REF!),OR(#REF!="Todos",Datos!$D3=IFERROR(VALUE(#REF!),#REF!)),OR(#REF!="Todos",Datos!$F3=#REF!)),1,0) -> #REF! | D3: Uso diario | E3: =IF(E2=0,0,COUNTIFS($B$2:$B$57,1,Datos!$F$2:$F$57,"A diario")/E2) -> #REF! | S3: =IF(ISNUMBER(SEARCH("Me resulta más difícil trabajar o estudiar sin usar IA",Datos!$AG3)),1,0) -> 1 | T3: =IF(ISNUMBER(SEARCH("Siento que retengo menos información cuando uso IA para resolver algo",Datos!$AG3)),1,0) -> 0 | U3: =IF(ISNUMBER(SEARCH("Siento que dependo de la IA para producir un mejor trabajo",Datos!$AG3)),1,0) -> 1 | V3: =IF(ISNUMBER(SEARCH("No he experimentado ninguna de estas situaciones",Datos!$AG3)),1,0) -> 0
A4: =Datos!A4 -> 16 | B4: =IF(AND(OR(#REF!="Todos",Datos!$E4=#REF!),OR(#REF!="Todos",Datos!$D4=IFERROR(VALUE(#REF!),#REF!)),OR(#REF!="Todos",Datos!$F4=#REF!)),1,0) -> #REF! | D4: Satisfacción positiva | E4: =IF(E2=0,0,(COUNTIFS($B$2:$B$57,1,Datos!$AF$2:$AF$57,"De acuerdo")+COUNTIFS($B$2:$B$57,1,Datos!$AF$2:$AF$57,"Totalmente de acuerdo"))/E2) -> #REF! | S4: =IF(ISNUMBER(SEARCH("Me resulta más difícil trabajar o estudiar sin usar IA",Datos!$AG4)),1,0) -> 1 | T4: =IF(ISNUMBER(SEARCH("Siento que retengo menos información cuando uso IA para resolver algo",Datos!$AG4)),1,0) -> 0 | U4: =IF(ISNUMBER(SEARCH("Siento que dependo de la IA para producir un mejor trabajo",Datos!$AG4)),1,0) -> 1 | V4: =IF(ISNUMBER(SEARCH("No he experimentado ninguna de estas situaciones",Datos!$AG4)),1,0) -> 0
A5: =Datos!A5 -> 17 | B5: =IF(AND(OR(#REF!="Todos",Datos!$E5=#REF!),OR(#REF!="Todos",Datos!$D5=IFERROR(VALUE(#REF!),#REF!)),OR(#REF!="Todos",Datos!$F5=#REF!)),1,0) -> #REF! | D5: Intención de continuar | E5: =IF(E2=0,0,(COUNTIFS($B$2:$B$57,1,Datos!$AE$2:$AE$57,"De acuerdo")+COUNTIFS($B$2:$B$57,1,Datos!$AE$2:$AE$57,"Totalmente de acuerdo"))/E2) -> #REF! | S5: =IF(ISNUMBER(SEARCH("Me resulta más difícil trabajar o estudiar sin usar IA",Datos!$AG5)),1,0) -> 0 | T5: =IF(ISNUMBER(SEARCH("Siento que retengo menos información cuando uso IA para resolver algo",Datos!$AG5)),1,0) -> 0 | U5: =IF(ISNUMBER(SEARCH("Siento que dependo de la IA para producir un mejor trabajo",Datos!$AG5)),1,0) -> 0 | V5: =IF(ISNUMBER(SEARCH("No he experimentado ninguna de estas situaciones",Datos!$AG5)),1,0) -> 1
A6: =Datos!A6 -> 18 | B6: =IF(AND(OR(#REF!="Todos",Datos!$E6=#REF!),OR(#REF!="Todos",Datos!$D6=IFERROR(VALUE(#REF!),#REF!)),OR(#REF!="Todos",Datos!$F6=#REF!)),1,0) -> #REF! | S6: =IF(ISNUMBER(SEARCH("Me resulta más difícil trabajar o estudiar sin usar IA",Datos!$AG6)),1,0) -> 0 | T6: =IF(ISNUMBER(SEARCH("Siento que retengo menos información cuando uso IA para resolver algo",Datos!$AG6)),1,0) -> 0 | U6: =IF(ISNUMBER(SEARCH("Siento que dependo de la IA para producir un mejor trabajo",Datos!$AG6)),1,0) -> 0 | V6: =IF(ISNUMBER(SEARCH("No he experimentado ninguna de estas situaciones",Datos!$AG6)),1,0) -> 1
A7: =Datos!A7 -> 19 | B7: =IF(AND(OR(#REF!="Todos",Datos!$E7=#REF!),OR(#REF!="Todos",Datos!$D7=IFERROR(VALUE(#REF!),#REF!)),OR(#REF!="Todos",Datos!$F7=#REF!)),1,0) -> #REF! | S7: =IF(ISNUMBER(SEARCH("Me resulta más difícil trabajar o estudiar sin usar IA",Datos!$AG7)),1,0) -> 1 | T7: =IF(ISNUMBER(SEARCH("Siento que retengo menos información cuando uso IA para resolver algo",Datos!$AG7)),1,0) -> 1 | U7: =IF(ISNUMBER(SEARCH("Siento que dependo de la IA para producir un mejor trabajo",Datos!$AG7)),1,0) -> 0 | V7: =IF(ISNUMBER(SEARCH("No he experimentado ninguna de estas situaciones",Datos!$AG7)),1,0) -> 0
A8: =Datos!A8 -> 20 | B8: =IF(AND(OR(#REF!="Todos",Datos!$E8=#REF!),OR(#REF!="Todos",Datos!$D8=IFERROR(VALUE(#REF!),#REF!)),OR(#REF!="Todos",Datos!$F8=#REF!)),1,0) -> #REF! | D8: Frecuencia | E8: Respuestas | G8: Año de ingreso | H8: Respuestas | J8: Herramienta | K8: % uso reportado | M8: Actividad | N8: % aceptable | S8: =IF(ISNUMBER(SEARCH("Me resulta más difícil trabajar o estudiar sin usar IA",Datos!$AG8)),1,0) -> 0 | T8: =IF(ISNUMBER(SEARCH("Siento que retengo menos información cuando uso IA para resolver algo",Datos!$AG8)),1,0) -> 0 | U8: =IF(ISNUMBER(SEARCH("Siento que dependo de la IA para producir un mejor trabajo",Datos!$AG8)),1,0) -> 0 | V8: =IF(ISNUMBER(SEARCH("No he experimentado ninguna de estas situaciones",Datos!$AG8)),1,0) -> 1 | AA8: Año de ingreso | AB8: Respuestas | AD8: Percepción | AE8: % | AG8: Horas por semana | AH8: % | AJ8: Verificación | AK8: % | AM8: Cambio de calidad | AN8: % | AP8: Conciencia de riesgos | AQ8: % | AS8: Capacitación | AT8: % | AV8: Situaciones | AW8: % | AY8: Influencia | AZ8: % | BB8: Política | BC8: %
A9: =Datos!A9 -> 21 | B9: =IF(AND(OR(#REF!="Todos",Datos!$E9=#REF!),OR(#REF!="Todos",Datos!$D9=IFERROR(VALUE(#REF!),#REF!)),OR(#REF!="Todos",Datos!$F9=#REF!)),1,0) -> #REF! | D9: A diario | E9: =COUNTIFS($B$2:$B$57,1,Datos!$F$2:$F$57,"A diario") -> 0 | G9: 2017 | H9: =COUNTIFS($B$2:$B$57,1,Datos!$D$2:$D$57,G9) -> 0 | J9: ChatGPT | K9: =IF($E$2=0,0,100*COUNTIFS($B$2:$B$57,1,Datos!$G$2:$G$57,"<>Nunca",Datos!$G$2:$G$57,"<>")/$E$2) -> #REF! | M9: Explicar conceptos | N9: =IF($E$2=0,0,100*(COUNTIFS($B$2:$B$57,1,Datos!$T$2:$T$57,"Aceptable")+COUNTIFS($B$2:$B$57,1,Datos!$T$2:$T$57,"Totalmente aceptable"))/$E$2) -> #REF! | S9: =IF(ISNUMBER(SEARCH("Me resulta más difícil trabajar o estudiar sin usar IA",Datos!$AG9)),1,0) -> 0 | T9: =IF(ISNUMBER(SEARCH("Siento que retengo menos información cuando uso IA para resolver algo",Datos!$AG9)),1,0) -> 0 | U9: =IF(ISNUMBER(SEARCH("Siento que dependo de la IA para producir un mejor trabajo",Datos!$AG9)),1,0) -> 0 | V9: =IF(ISNUMBER(SEARCH("No he experimentado ninguna de estas situaciones",Datos!$AG9)),1,0) -> 1 | AA9: 2017 | AB9: =COUNTIFS($B$2:$B$57,1,Datos!$D$2:$D$57,AA9) -> 0 | AD9: =D18 -> Ayuda a entender temas complejos | AE9: =100*E18 -> #REF! | AG9: =G18 -> Menos de 1 hora | AH9: =100*H18 -> #REF! | AJ9: =D27 -> Siempre | AK9: =100*E27 -> #REF! | AM9: =G27 -> Ha mejorado mucho | AN9: =100*H27 -> #REF! | AP9: =J27 -> Muy consciente | AQ9: =100*K27 -> #REF! | AS9: =M27 -> Muy dispuesto | AT9: =100*N27 -> #REF! | AV9: =J18 -> Dificultad para trabajar/estudiar sin IA | AW9: =K18 -> #REF! | AY9: =M18 -> Decisión propia | AZ9: =N18 -> #REF! | BB9: =P18 -> Se anima a usarla lo más posible | BC9: =Q18 -> #REF!
A10: =Datos!A10 -> 22 | B10: =IF(AND(OR(#REF!="Todos",Datos!$E10=#REF!),OR(#REF!="Todos",Datos!$D10=IFERROR(VALUE(#REF!),#REF!)),OR(#REF!="Todos",Datos!$F10=#REF!)),1,0) -> #REF! | D10: Semanalmente | E10: =COUNTIFS($B$2:$B$57,1,Datos!$F$2:$F$57,"Semanalmente") -> 0 | G10: 2019 | H10: =COUNTIFS($B$2:$B$57,1,Datos!$D$2:$D$57,G10) -> 0 | J10: Copilot | K10: =IF($E$2=0,0,100*COUNTIFS($B$2:$B$57,1,Datos!$H$2:$H$57,"<>Nunca",Datos!$H$2:$H$57,"<>")/$E$2) -> #REF! | M10: Resumir artículos | N10: =IF($E$2=0,0,100*(COUNTIFS($B$2:$B$57,1,Datos!$U$2:$U$57,"Aceptable")+COUNTIFS($B$2:$B$57,1,Datos!$U$2:$U$57,"Totalmente aceptable"))/$E$2) -> #REF! | S10: =IF(ISNUMBER(SEARCH("Me resulta más difícil trabajar o estudiar sin usar IA",Datos!$AG10)),1,0) -> 0 | T10: =IF(ISNUMBER(SEARCH("Siento que retengo menos información cuando uso IA para resolver algo",Datos!$AG10)),1,0) -> 0 | U10: =IF(ISNUMBER(SEARCH("Siento que dependo de la IA para producir un mejor trabajo",Datos!$AG10)),1,0) -> 0 | V10: =IF(ISNUMBER(SEARCH("No he experimentado ninguna de estas situaciones",Datos!$AG10)),1,0) -> 1 | AA10: 2019 | AB10: =COUNTIFS($B$2:$B$57,1,Datos!$D$2:$D$57,AA10) -> 0 | AD10: =D19 -> Es fácil de usar | AE10: =100*E19 -> #REF! | AG10: =G19 -> 1 a 3 horas | AH10: =100*H19 -> #REF! | AJ10: =D28 -> Frecuentemente | AK10: =100*E28 -> #REF! | AM10: =G28 -> Ha mejorado algo | AN10: =100*H28 -> #REF! | AP10: =J28 -> Consciente | AQ10: =100*K28 -> #REF! | AS10: =M28 -> Dispuesto | AT10: =100*N28 -> #REF! | AV10: =J19 -> Menor retención de información | AW10: =K19 -> #REF! | AY10: =M19 -> Influencia de compañeros de estudio | AZ10: =N19 -> #REF! | BB10: =P19 -> Se anima a usarla, pero con límites claros | BC10: =Q19 -> #REF!
A11: =Datos!A11 -> 23 | B11: =IF(AND(OR(#REF!="Todos",Datos!$E11=#REF!),OR(#REF!="Todos",Datos!$D11=IFERROR(VALUE(#REF!),#REF!)),OR(#REF!="Todos",Datos!$F11=#REF!)),1,0) -> #REF! | D11: Mensualmente | E11: =COUNTIFS($B$2:$B$57,1,Datos!$F$2:$F$57,"Mensualmente") -> 0 | G11: 2021 | H11: =COUNTIFS($B$2:$B$57,1,Datos!$D$2:$D$57,G11) -> 0 | J11: Gemini | K11: =IF($E$2=0,0,100*COUNTIFS($B$2:$B$57,1,Datos!$I$2:$I$57,"<>Nunca",Datos!$I$2:$I$57,"<>")/$E$2) -> #REF! | M11: Ideas investigación | N11: =IF($E$2=0,0,100*(COUNTIFS($B$2:$B$57,1,Datos!$V$2:$V$57,"Aceptable")+COUNTIFS($B$2:$B$57,1,Datos!$V$2:$V$57,"Totalmente aceptable"))/$E$2) -> #REF! | S11: =IF(ISNUMBER(SEARCH("Me resulta más difícil trabajar o estudiar sin usar IA",Datos!$AG11)),1,0) -> 0 | T11: =IF(ISNUMBER(SEARCH("Siento que retengo menos información cuando uso IA para resolver algo",Datos!$AG11)),1,0) -> 1 | U11: =IF(ISNUMBER(SEARCH("Siento que dependo de la IA para producir un mejor trabajo",Datos!$AG11)),1,0) -> 1 | V11: =IF(ISNUMBER(SEARCH("No he experimentado ninguna de estas situaciones",Datos!$AG11)),1,0) -> 0 | AA11: 2021 | AB11: =COUNTIFS($B$2:$B$57,1,Datos!$D$2:$D$57,AA11) -> 0 | AD11: =D20 -> Confío en sus resultados | AE11: =100*E20 -> #REF! | AG11: =G20 -> 3 a 6 horas | AH11: =100*H20 -> #REF! | AJ11: =D29 -> Algunas veces | AK11: =100*E29 -> #REF! | AM11: =G29 -> No ha cambiado | AN11: =100*H29 -> #REF! | AP11: =J29 -> Moderadamente consciente | AQ11: =100*K29 -> #REF! | AS11: =M29 -> Neutral | AT11: =100*N29 -> #REF! | AV11: =J20 -> Dependencia para producir mejor trabajo | AW11: =K20 -> #REF! | AY11: =M20 -> Sugerencia de un catedrático | AZ11: =N20 -> #REF! | BB11: =P20 -> Se desalienta, permitida en pocos casos | BC11: =Q20 -> #REF!
A12: =Datos!A12 -> 24 | B12: =IF(AND(OR(#REF!="Todos",Datos!$E12=#REF!),OR(#REF!="Todos",Datos!$D12=IFERROR(VALUE(#REF!),#REF!)),OR(#REF!="Todos",Datos!$F12=#REF!)),1,0) -> #REF! | D12: Rara vez | E12: =COUNTIFS($B$2:$B$57,1,Datos!$F$2:$F$57,"Rara vez (algunas veces al mes)") -> 0 | G12: 2022 | H12: =COUNTIFS($B$2:$B$57,1,Datos!$D$2:$D$57,G12) -> 0 | J12: Grok | K12: =IF($E$2=0,0,100*COUNTIFS($B$2:$B$57,1,Datos!$J$2:$J$57,"<>Nunca",Datos!$J$2:$J$57,"<>")/$E$2) -> #REF! | M12: Estructurar ideas | N12: =IF($E$2=0,0,100*(COUNTIFS($B$2:$B$57,1,Datos!$W$2:$W$57,"Aceptable")+COUNTIFS($B$2:$B$57,1,Datos!$W$2:$W$57,"Totalmente aceptable"))/$E$2) -> #REF! | S12: =IF(ISNUMBER(SEARCH("Me resulta más difícil trabajar o estudiar sin usar IA",Datos!$AG12)),1,0) -> 0 | T12: =IF(ISNUMBER(SEARCH("Siento que retengo menos información cuando uso IA para resolver algo",Datos!$AG12)),1,0) -> 0 | U12: =IF(ISNUMBER(SEARCH("Siento que dependo de la IA para producir un mejor trabajo",Datos!$AG12)),1,0) -> 0 | V12: =IF(ISNUMBER(SEARCH("No he experimentado ninguna de estas situaciones",Datos!$AG12)),1,0) -> 1 | AA12: 2022 | AB12: =COUNTIFS($B$2:$B$57,1,Datos!$D$2:$D$57,AA12) -> 0 | AD12: =D21 -> Planeo seguir usándola | AE12: =100*E21 -> #REF! | AG12: =G21 -> 6 a 10 horas | AH12: =100*H21 -> #REF! | AJ12: =D30 -> Rara vez | AK12: =100*E30 -> #REF! | AM12: =G30 -> Ha empeorado algo | AN12: =100*H30 -> #REF! | AP12: =J30 -> Poco consciente | AQ12: =100*K30 -> #REF! | AS12: =M30 -> Poco dispuesto | AT12: =100*N30 -> #REF! | AV12: =J21 -> Ninguna de las anteriores | AW12: =K21 -> #REF! | AY12: =M21 -> Requisito de un curso o trabajo | AZ12: =N21 -> #REF! | BB12: =P21 -> Está prohibida por completo | BC12: =Q21 -> #REF!
A13: =Datos!A13 -> 25 | B13: =IF(AND(OR(#REF!="Todos",Datos!$E13=#REF!),OR(#REF!="Todos",Datos!$D13=IFERROR(VALUE(#REF!),#REF!)),OR(#REF!="Todos",Datos!$F13=#REF!)),1,0) -> #REF! | D13: Nunca | E13: =COUNTIFS($B$2:$B$57,1,Datos!$F$2:$F$57,"Nunca") -> 0 | G13: 2023 | H13: =COUNTIFS($B$2:$B$57,1,Datos!$D$2:$D$57,G13) -> 0 | J13: Deepseek | K13: =IF($E$2=0,0,100*COUNTIFS($B$2:$B$57,1,Datos!$K$2:$K$57,"<>Nunca",Datos!$K$2:$K$57,"<>")/$E$2) -> #REF! | M13: Generar/editar texto | N13: =IF($E$2=0,0,100*(COUNTIFS($B$2:$B$57,1,Datos!$X$2:$X$57,"Aceptable")+COUNTIFS($B$2:$B$57,1,Datos!$X$2:$X$57,"Totalmente aceptable"))/$E$2) -> #REF! | S13: =IF(ISNUMBER(SEARCH("Me resulta más difícil trabajar o estudiar sin usar IA",Datos!$AG13)),1,0) -> 1 | T13: =IF(ISNUMBER(SEARCH("Siento que retengo menos información cuando uso IA para resolver algo",Datos!$AG13)),1,0) -> 0 | U13: =IF(ISNUMBER(SEARCH("Siento que dependo de la IA para producir un mejor trabajo",Datos!$AG13)),1,0) -> 0 | V13: =IF(ISNUMBER(SEARCH("No he experimentado ninguna de estas situaciones",Datos!$AG13)),1,0) -> 0 | AA13: 2023 | AB13: =COUNTIFS($B$2:$B$57,1,Datos!$D$2:$D$57,AA13) -> 0 | AD13: =D22 -> Estoy satisfecho con su uso | AE13: =100*E22 -> #REF! | AG13: =G22 -> Más de 10 horas | AH13: =100*H22 -> #REF! | AJ13: =D31 -> Nunca | AK13: =100*E31 -> #REF! | AM13: =G31 -> Ha empeorado mucho | AN13: =100*H31 -> #REF! | AP13: =J31 -> Nada consciente | AQ13: =100*K31 -> #REF! | AS13: =M31 -> Nada dispuesto | AT13: =100*N31 -> #REF! | AY13: =M22 -> Otro | AZ13: =N22 -> #REF! | BB13: =P22 -> No sé cuál es la política de mi universidad | BC13: =Q22 -> #REF!
A14: =Datos!A14 -> 26 | B14: =IF(AND(OR(#REF!="Todos",Datos!$E14=#REF!),OR(#REF!="Todos",Datos!$D14=IFERROR(VALUE(#REF!),#REF!)),OR(#REF!="Todos",Datos!$F14=#REF!)),1,0) -> #REF! | G14: 2024 | H14: =COUNTIFS($B$2:$B$57,1,Datos!$D$2:$D$57,G14) -> 0 | J14: Otra IA | K14: =IF($E$2=0,0,100*COUNTIFS($B$2:$B$57,1,Datos!$L$2:$L$57,"<>Nunca",Datos!$L$2:$L$57,"<>")/$E$2) -> #REF! | M14: Apoyos visuales | N14: =IF($E$2=0,0,100*(COUNTIFS($B$2:$B$57,1,Datos!$Y$2:$Y$57,"Aceptable")+COUNTIFS($B$2:$B$57,1,Datos!$Y$2:$Y$57,"Totalmente aceptable"))/$E$2) -> #REF! | S14: =IF(ISNUMBER(SEARCH("Me resulta más difícil trabajar o estudiar sin usar IA",Datos!$AG14)),1,0) -> 1 | T14: =IF(ISNUMBER(SEARCH("Siento que retengo menos información cuando uso IA para resolver algo",Datos!$AG14)),1,0) -> 0 | U14: =IF(ISNUMBER(SEARCH("Siento que dependo de la IA para producir un mejor trabajo",Datos!$AG14)),1,0) -> 0 | V14: =IF(ISNUMBER(SEARCH("No he experimentado ninguna de estas situaciones",Datos!$AG14)),1,0) -> 0 | AA14: 2024 | AB14: =COUNTIFS($B$2:$B$57,1,Datos!$D$2:$D$57,AA14) -> 0
A15: =Datos!A15 -> 27 | B15: =IF(AND(OR(#REF!="Todos",Datos!$E15=#REF!),OR(#REF!="Todos",Datos!$D15=IFERROR(VALUE(#REF!),#REF!)),OR(#REF!="Todos",Datos!$F15=#REF!)),1,0) -> #REF! | G15: 2025 | H15: =COUNTIFS($B$2:$B$57,1,Datos!$D$2:$D$57,G15) -> 0 | S15: =IF(ISNUMBER(SEARCH("Me resulta más difícil trabajar o estudiar sin usar IA",Datos!$AG15)),1,0) -> 1 | T15: =IF(ISNUMBER(SEARCH("Siento que retengo menos información cuando uso IA para resolver algo",Datos!$AG15)),1,0) -> 0 | U15: =IF(ISNUMBER(SEARCH("Siento que dependo de la IA para producir un mejor trabajo",Datos!$AG15)),1,0) -> 0 | V15: =IF(ISNUMBER(SEARCH("No he experimentado ninguna de estas situaciones",Datos!$AG15)),1,0) -> 0 | AA15: 2025 | AB15: =COUNTIFS($B$2:$B$57,1,Datos!$D$2:$D$57,AA15) -> 0
A16: =Datos!A16 -> 28 | B16: =IF(AND(OR(#REF!="Todos",Datos!$E16=#REF!),OR(#REF!="Todos",Datos!$D16=IFERROR(VALUE(#REF!),#REF!)),OR(#REF!="Todos",Datos!$F16=#REF!)),1,0) -> #REF! | G16: 2026 | H16: =COUNTIFS($B$2:$B$57,1,Datos!$D$2:$D$57,G16) -> 0 | S16: =IF(ISNUMBER(SEARCH("Me resulta más difícil trabajar o estudiar sin usar IA",Datos!$AG16)),1,0) -> 0 | T16: =IF(ISNUMBER(SEARCH("Siento que retengo menos información cuando uso IA para resolver algo",Datos!$AG16)),1,0) -> 0 | U16: =IF(ISNUMBER(SEARCH("Siento que dependo de la IA para producir un mejor trabajo",Datos!$AG16)),1,0) -> 0 | V16: =IF(ISNUMBER(SEARCH("No he experimentado ninguna de estas situaciones",Datos!$AG16)),1,0) -> 1 | AA16: 2026 | AB16: =COUNTIFS($B$2:$B$57,1,Datos!$D$2:$D$57,AA16) -> 0
A17: =Datos!A17 -> 29 | B17: =IF(AND(OR(#REF!="Todos",Datos!$E17=#REF!),OR(#REF!="Todos",Datos!$D17=IFERROR(VALUE(#REF!),#REF!)),OR(#REF!="Todos",Datos!$F17=#REF!)),1,0) -> #REF! | D17: Percepción | E17: % de acuerdo | G17: Horas por semana | H17: % respuestas | J17: Situación | K17: % respuestas | M17: Influencia principal | N17: % respuestas | P17: Percepción de política | Q17: % respuestas | S17: =IF(ISNUMBER(SEARCH("Me resulta más difícil trabajar o estudiar sin usar IA",Datos!$AG17)),1,0) -> 0 | T17: =IF(ISNUMBER(SEARCH("Siento que retengo menos información cuando uso IA para resolver algo",Datos!$AG17)),1,0) -> 0 | U17: =IF(ISNUMBER(SEARCH("Siento que dependo de la IA para producir un mejor trabajo",Datos!$AG17)),1,0) -> 0 | V17: =IF(ISNUMBER(SEARCH("No he experimentado ninguna de estas situaciones",Datos!$AG17)),1,0) -> 1
A18: =Datos!A18 -> 30 | B18: =IF(AND(OR(#REF!="Todos",Datos!$E18=#REF!),OR(#REF!="Todos",Datos!$D18=IFERROR(VALUE(#REF!),#REF!)),OR(#REF!="Todos",Datos!$F18=#REF!)),1,0) -> #REF! | D18: Ayuda a entender temas complejos | E18: =IF($E$2=0,0,(COUNTIFS($B$2:$B$57,1,Datos!$AB$2:$AB$57,"De acuerdo")+COUNTIFS($B$2:$B$57,1,Datos!$AB$2:$AB$57,"Totalmente de acuerdo"))/$E$2) -> #REF! | G18: Menos de 1 hora | H18: =IF($E$2=0,0,COUNTIFS($B$2:$B$57,1,Datos!$M$2:$M$57,G18)/$E$2) -> #REF! | J18: Dificultad para trabajar/estudiar sin IA | K18: =IF($E$2=0,0,SUMIFS($S$2:$S$57,$B$2:$B$57,1)/$E$2) -> #REF! | M18: Decisión propia | N18: =IF($E$2=0,0,COUNTIFS($B$2:$B$57,1,Datos!$AH$2:$AH$57,M18)/$E$2) -> #REF! | P18: Se anima a usarla lo más posible | Q18: =IF($E$2=0,0,COUNTIFS($B$2:$B$57,1,Datos!$AI$2:$AI$57,P18)/$E$2) -> #REF! | S18: =IF(ISNUMBER(SEARCH("Me resulta más difícil trabajar o estudiar sin usar IA",Datos!$AG18)),1,0) -> 0 | T18: =IF(ISNUMBER(SEARCH("Siento que retengo menos información cuando uso IA para resolver algo",Datos!$AG18)),1,0) -> 1 | U18: =IF(ISNUMBER(SEARCH("Siento que dependo de la IA para producir un mejor trabajo",Datos!$AG18)),1,0) -> 0 | V18: =IF(ISNUMBER(SEARCH("No he experimentado ninguna de estas situaciones",Datos!$AG18)),1,0) -> 0
